[2024-05-08T14:23:37.562+0000] {taskinstance.py:1979} INFO - Dependencies all met for dep_context=non-requeueable deps ti=<TaskInstance: spotify_data_pipeline.load_data_to_postgres scheduled__2024-05-07T00:00:00+00:00 [queued]>
[2024-05-08T14:23:37.586+0000] {taskinstance.py:1979} INFO - Dependencies all met for dep_context=requeueable deps ti=<TaskInstance: spotify_data_pipeline.load_data_to_postgres scheduled__2024-05-07T00:00:00+00:00 [queued]>
[2024-05-08T14:23:37.587+0000] {taskinstance.py:2193} INFO - Starting attempt 2 of 2
[2024-05-08T14:23:37.646+0000] {taskinstance.py:2217} INFO - Executing <Task(PythonOperator): load_data_to_postgres> on 2024-05-07 00:00:00+00:00
[2024-05-08T14:23:37.669+0000] {standard_task_runner.py:87} INFO - Running: ['***', 'tasks', 'run', 'spotify_data_pipeline', 'load_data_to_postgres', 'scheduled__2024-05-07T00:00:00+00:00', '--job-id', '447', '--raw', '--subdir', 'DAGS_FOLDER/main15.py', '--cfg-path', '/tmp/tmp4i1uom3a']
[2024-05-08T14:23:37.671+0000] {standard_task_runner.py:88} INFO - Job 447: Subtask load_data_to_postgres
[2024-05-08T14:23:37.662+0000] {standard_task_runner.py:60} INFO - Started process 101 to run task
[2024-05-08T14:23:37.836+0000] {task_command.py:423} INFO - Running <TaskInstance: spotify_data_pipeline.load_data_to_postgres scheduled__2024-05-07T00:00:00+00:00 [running]> on host 8aebc95d8de6
[2024-05-08T14:23:38.044+0000] {taskinstance.py:2513} INFO - Exporting env vars: AIRFLOW_CTX_DAG_OWNER='***' AIRFLOW_CTX_DAG_ID='spotify_data_pipeline' AIRFLOW_CTX_TASK_ID='load_data_to_postgres' AIRFLOW_CTX_EXECUTION_DATE='2024-05-07T00:00:00+00:00' AIRFLOW_CTX_TRY_NUMBER='2' AIRFLOW_CTX_DAG_RUN_ID='scheduled__2024-05-07T00:00:00+00:00'
[2024-05-08T14:23:38.048+0000] {taskinstance.py:2731} ERROR - Task failed with exception
Traceback (most recent call last):
  File "/home/airflow/.local/lib/python3.8/site-packages/airflow/models/taskinstance.py", line 444, in _execute_task
    result = _execute_callable(context=context, **execute_callable_kwargs)
  File "/home/airflow/.local/lib/python3.8/site-packages/airflow/models/taskinstance.py", line 414, in _execute_callable
    return execute_callable(context=context, **execute_callable_kwargs)
  File "/home/airflow/.local/lib/python3.8/site-packages/airflow/operators/python.py", line 200, in execute
    return_value = self.execute_callable()
  File "/home/airflow/.local/lib/python3.8/site-packages/airflow/operators/python.py", line 217, in execute_callable
    return self.python_callable(*self.op_args, **self.op_kwargs)
TypeError: load_data_to_postgres() missing 1 required positional argument: 'df'
[2024-05-08T14:23:38.067+0000] {taskinstance.py:1149} INFO - Marking task as FAILED. dag_id=spotify_data_pipeline, task_id=load_data_to_postgres, execution_date=20240507T000000, start_date=20240508T142337, end_date=20240508T142338
[2024-05-08T14:23:38.093+0000] {standard_task_runner.py:107} ERROR - Failed to execute job 447 for task load_data_to_postgres (load_data_to_postgres() missing 1 required positional argument: 'df'; 101)
[2024-05-08T14:23:38.141+0000] {local_task_job_runner.py:234} INFO - Task exited with return code 1
[2024-05-08T14:23:38.175+0000] {taskinstance.py:3312} INFO - 0 downstream tasks scheduled from follow-on schedule check
