[2024-05-08T15:20:27.705+0000] {taskinstance.py:1979} INFO - Dependencies all met for dep_context=non-requeueable deps ti=<TaskInstance: spotify_data_pipeline.validate_data manual__2024-05-08T15:19:51.694032+00:00 [queued]>
[2024-05-08T15:20:27.719+0000] {taskinstance.py:1979} INFO - Dependencies all met for dep_context=requeueable deps ti=<TaskInstance: spotify_data_pipeline.validate_data manual__2024-05-08T15:19:51.694032+00:00 [queued]>
[2024-05-08T15:20:27.720+0000] {taskinstance.py:2193} INFO - Starting attempt 1 of 2
[2024-05-08T15:20:27.738+0000] {taskinstance.py:2217} INFO - Executing <Task(PythonOperator): validate_data> on 2024-05-08 15:19:51.694032+00:00
[2024-05-08T15:20:27.746+0000] {standard_task_runner.py:60} INFO - Started process 1121 to run task
[2024-05-08T15:20:27.758+0000] {standard_task_runner.py:87} INFO - Running: ['***', 'tasks', 'run', 'spotify_data_pipeline', 'validate_data', 'manual__2024-05-08T15:19:51.694032+00:00', '--job-id', '495', '--raw', '--subdir', 'DAGS_FOLDER/how.py', '--cfg-path', '/tmp/tmp1dpttx03']
[2024-05-08T15:20:27.760+0000] {standard_task_runner.py:88} INFO - Job 495: Subtask validate_data
[2024-05-08T15:20:27.842+0000] {task_command.py:423} INFO - Running <TaskInstance: spotify_data_pipeline.validate_data manual__2024-05-08T15:19:51.694032+00:00 [running]> on host 8aebc95d8de6
[2024-05-08T15:20:27.947+0000] {taskinstance.py:2513} INFO - Exporting env vars: AIRFLOW_CTX_DAG_OWNER='***' AIRFLOW_CTX_DAG_ID='spotify_data_pipeline' AIRFLOW_CTX_TASK_ID='validate_data' AIRFLOW_CTX_EXECUTION_DATE='2024-05-08T15:19:51.694032+00:00' AIRFLOW_CTX_TRY_NUMBER='1' AIRFLOW_CTX_DAG_RUN_ID='manual__2024-05-08T15:19:51.694032+00:00'
[2024-05-08T15:20:27.949+0000] {taskinstance.py:2731} ERROR - Task failed with exception
Traceback (most recent call last):
  File "/home/airflow/.local/lib/python3.8/site-packages/airflow/models/taskinstance.py", line 444, in _execute_task
    result = _execute_callable(context=context, **execute_callable_kwargs)
  File "/home/airflow/.local/lib/python3.8/site-packages/airflow/models/taskinstance.py", line 414, in _execute_callable
    return execute_callable(context=context, **execute_callable_kwargs)
  File "/home/airflow/.local/lib/python3.8/site-packages/airflow/operators/python.py", line 200, in execute
    return_value = self.execute_callable()
  File "/home/airflow/.local/lib/python3.8/site-packages/airflow/operators/python.py", line 217, in execute_callable
    return self.python_callable(*self.op_args, **self.op_kwargs)
TypeError: validate_data() missing 1 required positional argument: 'df1'
[2024-05-08T15:20:27.961+0000] {taskinstance.py:1149} INFO - Marking task as UP_FOR_RETRY. dag_id=spotify_data_pipeline, task_id=validate_data, execution_date=20240508T151951, start_date=20240508T152027, end_date=20240508T152027
[2024-05-08T15:20:27.980+0000] {standard_task_runner.py:107} ERROR - Failed to execute job 495 for task validate_data (validate_data() missing 1 required positional argument: 'df1'; 1121)
[2024-05-08T15:20:28.011+0000] {local_task_job_runner.py:234} INFO - Task exited with return code 1
[2024-05-08T15:20:28.039+0000] {taskinstance.py:3312} INFO - 0 downstream tasks scheduled from follow-on schedule check
