[2024-06-19T14:46:30.135+0000] {taskinstance.py:1979} INFO - Dependencies all met for dep_context=non-requeueable deps ti=<TaskInstance: spotify_data_pipeline.process_and_clean_data_task manual__2024-06-19T14:46:08.390164+00:00 [queued]>
[2024-06-19T14:46:30.159+0000] {taskinstance.py:1979} INFO - Dependencies all met for dep_context=requeueable deps ti=<TaskInstance: spotify_data_pipeline.process_and_clean_data_task manual__2024-06-19T14:46:08.390164+00:00 [queued]>
[2024-06-19T14:46:30.161+0000] {taskinstance.py:2193} INFO - Starting attempt 1 of 2
[2024-06-19T14:46:30.196+0000] {taskinstance.py:2217} INFO - Executing <Task(PythonOperator): process_and_clean_data_task> on 2024-06-19 14:46:08.390164+00:00
[2024-06-19T14:46:30.207+0000] {standard_task_runner.py:60} INFO - Started process 2552 to run task
[2024-06-19T14:46:30.215+0000] {standard_task_runner.py:87} INFO - Running: ['***', 'tasks', 'run', 'spotify_data_pipeline', 'process_and_clean_data_task', 'manual__2024-06-19T14:46:08.390164+00:00', '--job-id', '1249', '--raw', '--subdir', 'DAGS_FOLDER/main15.py', '--cfg-path', '/tmp/tmp9x5rgt2o']
[2024-06-19T14:46:30.217+0000] {standard_task_runner.py:88} INFO - Job 1249: Subtask process_and_clean_data_task
[2024-06-19T14:46:30.298+0000] {task_command.py:423} INFO - Running <TaskInstance: spotify_data_pipeline.process_and_clean_data_task manual__2024-06-19T14:46:08.390164+00:00 [running]> on host 87b4d1457810
[2024-06-19T14:46:30.503+0000] {taskinstance.py:2513} INFO - Exporting env vars: AIRFLOW_CTX_DAG_OWNER='***' AIRFLOW_CTX_DAG_ID='spotify_data_pipeline' AIRFLOW_CTX_TASK_ID='process_and_clean_data_task' AIRFLOW_CTX_EXECUTION_DATE='2024-06-19T14:46:08.390164+00:00' AIRFLOW_CTX_TRY_NUMBER='1' AIRFLOW_CTX_DAG_RUN_ID='manual__2024-06-19T14:46:08.390164+00:00'
[2024-06-19T14:46:31.569+0000] {logging_mixin.py:188} INFO - Table created successfully
[2024-06-19T14:46:31.590+0000] {taskinstance.py:2731} ERROR - Task failed with exception
Traceback (most recent call last):
  File "/home/airflow/.local/lib/python3.8/site-packages/airflow/models/taskinstance.py", line 444, in _execute_task
    result = _execute_callable(context=context, **execute_callable_kwargs)
  File "/home/airflow/.local/lib/python3.8/site-packages/airflow/models/taskinstance.py", line 414, in _execute_callable
    return execute_callable(context=context, **execute_callable_kwargs)
  File "/home/airflow/.local/lib/python3.8/site-packages/airflow/operators/python.py", line 200, in execute
    return_value = self.execute_callable()
  File "/home/airflow/.local/lib/python3.8/site-packages/airflow/operators/python.py", line 217, in execute_callable
    return self.python_callable(*self.op_args, **self.op_kwargs)
  File "/opt/airflow/dags/main15.py", line 261, in process_and_clean_data
    cur.execute(insert_query, values)
psycopg2.errors.UndefinedColumn: column "Added Date" of relation "songs" does not exist
LINE 2: ...e of Album", "Popularity", "Popularity Category", "Added Dat...
                                                             ^

[2024-06-19T14:46:31.609+0000] {taskinstance.py:1149} INFO - Marking task as UP_FOR_RETRY. dag_id=spotify_data_pipeline, task_id=process_and_clean_data_task, execution_date=20240619T144608, start_date=20240619T144630, end_date=20240619T144631
[2024-06-19T14:46:31.630+0000] {standard_task_runner.py:107} ERROR - Failed to execute job 1249 for task process_and_clean_data_task (column "Added Date" of relation "songs" does not exist
LINE 2: ...e of Album", "Popularity", "Popularity Category", "Added Dat...
                                                             ^
; 2552)
[2024-06-19T14:46:31.677+0000] {local_task_job_runner.py:234} INFO - Task exited with return code 1
[2024-06-19T14:46:31.701+0000] {taskinstance.py:3312} INFO - 0 downstream tasks scheduled from follow-on schedule check
