[2024-05-07T12:40:00.391+0000] {taskinstance.py:1979} INFO - Dependencies all met for dep_context=non-requeueable deps ti=<TaskInstance: spotify_data_pipeline.clean_transform_data manual__2024-05-07T12:38:28.176938+00:00 [queued]>
[2024-05-07T12:40:00.404+0000] {taskinstance.py:1979} INFO - Dependencies all met for dep_context=requeueable deps ti=<TaskInstance: spotify_data_pipeline.clean_transform_data manual__2024-05-07T12:38:28.176938+00:00 [queued]>
[2024-05-07T12:40:00.404+0000] {taskinstance.py:2193} INFO - Starting attempt 2 of 2
[2024-05-07T12:40:00.422+0000] {taskinstance.py:2217} INFO - Executing <Task(PythonOperator): clean_transform_data> on 2024-05-07 12:38:28.176938+00:00
[2024-05-07T12:40:00.429+0000] {standard_task_runner.py:60} INFO - Started process 220 to run task
[2024-05-07T12:40:00.436+0000] {standard_task_runner.py:87} INFO - Running: ['***', 'tasks', 'run', 'spotify_data_pipeline', 'clean_transform_data', 'manual__2024-05-07T12:38:28.176938+00:00', '--job-id', '342', '--raw', '--subdir', 'DAGS_FOLDER/main15.py', '--cfg-path', '/tmp/tmpa8gd1rn2']
[2024-05-07T12:40:00.438+0000] {standard_task_runner.py:88} INFO - Job 342: Subtask clean_transform_data
[2024-05-07T12:40:00.496+0000] {task_command.py:423} INFO - Running <TaskInstance: spotify_data_pipeline.clean_transform_data manual__2024-05-07T12:38:28.176938+00:00 [running]> on host 8aebc95d8de6
[2024-05-07T12:40:00.597+0000] {taskinstance.py:2513} INFO - Exporting env vars: AIRFLOW_CTX_DAG_OWNER='***' AIRFLOW_CTX_DAG_ID='spotify_data_pipeline' AIRFLOW_CTX_TASK_ID='clean_transform_data' AIRFLOW_CTX_EXECUTION_DATE='2024-05-07T12:38:28.176938+00:00' AIRFLOW_CTX_TRY_NUMBER='2' AIRFLOW_CTX_DAG_RUN_ID='manual__2024-05-07T12:38:28.176938+00:00'
[2024-05-07T12:40:00.623+0000] {taskinstance.py:2731} ERROR - Task failed with exception
Traceback (most recent call last):
  File "/home/airflow/.local/lib/python3.8/site-packages/airflow/models/taskinstance.py", line 444, in _execute_task
    result = _execute_callable(context=context, **execute_callable_kwargs)
  File "/home/airflow/.local/lib/python3.8/site-packages/airflow/models/taskinstance.py", line 414, in _execute_callable
    return execute_callable(context=context, **execute_callable_kwargs)
  File "/home/airflow/.local/lib/python3.8/site-packages/airflow/operators/python.py", line 200, in execute
    return_value = self.execute_callable()
  File "/home/airflow/.local/lib/python3.8/site-packages/airflow/operators/python.py", line 217, in execute_callable
    return self.python_callable(*self.op_args, **self.op_kwargs)
  File "/opt/airflow/dags/main15.py", line 316, in clean_and_transform_data
    df1['Popularity Category'] = pd.cut(df1['Popularity'], bins=popularity_bins, labels=popularity_labels, right=False)
  File "/home/airflow/.local/lib/python3.8/site-packages/pandas/core/frame.py", line 3761, in __getitem__
    indexer = self.columns.get_loc(key)
  File "/home/airflow/.local/lib/python3.8/site-packages/pandas/core/indexes/range.py", line 349, in get_loc
    raise KeyError(key)
KeyError: 'Popularity'
[2024-05-07T12:40:00.641+0000] {taskinstance.py:1149} INFO - Marking task as FAILED. dag_id=spotify_data_pipeline, task_id=clean_transform_data, execution_date=20240507T123828, start_date=20240507T124000, end_date=20240507T124000
[2024-05-07T12:40:00.658+0000] {standard_task_runner.py:107} ERROR - Failed to execute job 342 for task clean_transform_data ('Popularity'; 220)
[2024-05-07T12:40:00.689+0000] {local_task_job_runner.py:234} INFO - Task exited with return code 1
[2024-05-07T12:40:00.719+0000] {taskinstance.py:3312} INFO - 0 downstream tasks scheduled from follow-on schedule check
