[2024-06-03T09:35:01.352+0000] {taskinstance.py:1979} INFO - Dependencies all met for dep_context=non-requeueable deps ti=<TaskInstance: spotify_data_pipeline.process_and_clean_data_task scheduled__2024-05-28T00:00:00+00:00 [queued]>
[2024-06-03T09:35:01.385+0000] {taskinstance.py:1979} INFO - Dependencies all met for dep_context=requeueable deps ti=<TaskInstance: spotify_data_pipeline.process_and_clean_data_task scheduled__2024-05-28T00:00:00+00:00 [queued]>
[2024-06-03T09:35:01.387+0000] {taskinstance.py:2193} INFO - Starting attempt 2 of 2
[2024-06-03T09:35:01.443+0000] {taskinstance.py:2217} INFO - Executing <Task(PythonOperator): process_and_clean_data_task> on 2024-05-28 00:00:00+00:00
[2024-06-03T09:35:01.468+0000] {standard_task_runner.py:60} INFO - Started process 447 to run task
[2024-06-03T09:35:01.475+0000] {standard_task_runner.py:87} INFO - Running: ['***', 'tasks', 'run', 'spotify_data_pipeline', 'process_and_clean_data_task', 'scheduled__2024-05-28T00:00:00+00:00', '--job-id', '1078', '--raw', '--subdir', 'DAGS_FOLDER/main15.py', '--cfg-path', '/tmp/tmpoujwogt_']
[2024-06-03T09:35:01.478+0000] {standard_task_runner.py:88} INFO - Job 1078: Subtask process_and_clean_data_task
[2024-06-03T09:35:01.612+0000] {task_command.py:423} INFO - Running <TaskInstance: spotify_data_pipeline.process_and_clean_data_task scheduled__2024-05-28T00:00:00+00:00 [running]> on host 87b4d1457810
[2024-06-03T09:35:01.799+0000] {taskinstance.py:2513} INFO - Exporting env vars: AIRFLOW_CTX_DAG_OWNER='***' AIRFLOW_CTX_DAG_ID='spotify_data_pipeline' AIRFLOW_CTX_TASK_ID='process_and_clean_data_task' AIRFLOW_CTX_EXECUTION_DATE='2024-05-28T00:00:00+00:00' AIRFLOW_CTX_TRY_NUMBER='2' AIRFLOW_CTX_DAG_RUN_ID='scheduled__2024-05-28T00:00:00+00:00'
[2024-06-03T09:35:02.416+0000] {taskinstance.py:2731} ERROR - Task failed with exception
Traceback (most recent call last):
  File "/home/airflow/.local/lib/python3.8/site-packages/airflow/models/taskinstance.py", line 444, in _execute_task
    result = _execute_callable(context=context, **execute_callable_kwargs)
  File "/home/airflow/.local/lib/python3.8/site-packages/airflow/models/taskinstance.py", line 414, in _execute_callable
    return execute_callable(context=context, **execute_callable_kwargs)
  File "/home/airflow/.local/lib/python3.8/site-packages/airflow/operators/python.py", line 200, in execute
    return_value = self.execute_callable()
  File "/home/airflow/.local/lib/python3.8/site-packages/airflow/operators/python.py", line 217, in execute_callable
    return self.python_callable(*self.op_args, **self.op_kwargs)
  File "/opt/airflow/dags/main15.py", line 210, in process_and_clean_data
    conn = psycopg2.connect(
  File "/home/airflow/.local/lib/python3.8/site-packages/psycopg2/__init__.py", line 122, in connect
    conn = _connect(dsn, connection_factory=connection_factory, **kwasync)
psycopg2.OperationalError: connection to server at "host.docker.internal" (192.168.65.254), port 5432 failed: FATAL:  password authentication failed for user "postgres"

[2024-06-03T09:35:02.438+0000] {taskinstance.py:1149} INFO - Marking task as FAILED. dag_id=spotify_data_pipeline, task_id=process_and_clean_data_task, execution_date=20240528T000000, start_date=20240603T093501, end_date=20240603T093502
[2024-06-03T09:35:02.469+0000] {standard_task_runner.py:107} ERROR - Failed to execute job 1078 for task process_and_clean_data_task (connection to server at "host.docker.internal" (192.168.65.254), port 5432 failed: FATAL:  password authentication failed for user "postgres"
; 447)
[2024-06-03T09:35:02.502+0000] {local_task_job_runner.py:234} INFO - Task exited with return code 1
[2024-06-03T09:35:02.534+0000] {taskinstance.py:3312} INFO - 0 downstream tasks scheduled from follow-on schedule check
