[2024-05-08T14:23:14.714+0000] {taskinstance.py:1979} INFO - Dependencies all met for dep_context=non-requeueable deps ti=<TaskInstance: spotify_data_pipeline.validate_data scheduled__2024-05-07T00:00:00+00:00 [queued]>
[2024-05-08T14:23:14.727+0000] {taskinstance.py:1979} INFO - Dependencies all met for dep_context=requeueable deps ti=<TaskInstance: spotify_data_pipeline.validate_data scheduled__2024-05-07T00:00:00+00:00 [queued]>
[2024-05-08T14:23:14.728+0000] {taskinstance.py:2193} INFO - Starting attempt 1 of 2
[2024-05-08T14:23:14.747+0000] {taskinstance.py:2217} INFO - Executing <Task(PythonOperator): validate_data> on 2024-05-07 00:00:00+00:00
[2024-05-08T14:23:14.757+0000] {standard_task_runner.py:60} INFO - Started process 90 to run task
[2024-05-08T14:23:14.764+0000] {standard_task_runner.py:87} INFO - Running: ['***', 'tasks', 'run', 'spotify_data_pipeline', 'validate_data', 'scheduled__2024-05-07T00:00:00+00:00', '--job-id', '446', '--raw', '--subdir', 'DAGS_FOLDER/how.py', '--cfg-path', '/tmp/tmpz_25oruu']
[2024-05-08T14:23:14.767+0000] {standard_task_runner.py:88} INFO - Job 446: Subtask validate_data
[2024-05-08T14:23:14.842+0000] {task_command.py:423} INFO - Running <TaskInstance: spotify_data_pipeline.validate_data scheduled__2024-05-07T00:00:00+00:00 [running]> on host 8aebc95d8de6
[2024-05-08T14:23:14.978+0000] {taskinstance.py:2513} INFO - Exporting env vars: AIRFLOW_CTX_DAG_OWNER='***' AIRFLOW_CTX_DAG_ID='spotify_data_pipeline' AIRFLOW_CTX_TASK_ID='validate_data' AIRFLOW_CTX_EXECUTION_DATE='2024-05-07T00:00:00+00:00' AIRFLOW_CTX_TRY_NUMBER='1' AIRFLOW_CTX_DAG_RUN_ID='scheduled__2024-05-07T00:00:00+00:00'
[2024-05-08T14:23:14.981+0000] {taskinstance.py:2731} ERROR - Task failed with exception
Traceback (most recent call last):
  File "/home/airflow/.local/lib/python3.8/site-packages/airflow/models/taskinstance.py", line 444, in _execute_task
    result = _execute_callable(context=context, **execute_callable_kwargs)
  File "/home/airflow/.local/lib/python3.8/site-packages/airflow/models/taskinstance.py", line 414, in _execute_callable
    return execute_callable(context=context, **execute_callable_kwargs)
  File "/home/airflow/.local/lib/python3.8/site-packages/airflow/operators/python.py", line 200, in execute
    return_value = self.execute_callable()
  File "/home/airflow/.local/lib/python3.8/site-packages/airflow/operators/python.py", line 217, in execute_callable
    return self.python_callable(*self.op_args, **self.op_kwargs)
TypeError: validate_data() missing 1 required positional argument: 'df1'
[2024-05-08T14:23:14.994+0000] {taskinstance.py:1149} INFO - Marking task as UP_FOR_RETRY. dag_id=spotify_data_pipeline, task_id=validate_data, execution_date=20240507T000000, start_date=20240508T142314, end_date=20240508T142314
[2024-05-08T14:23:15.024+0000] {standard_task_runner.py:107} ERROR - Failed to execute job 446 for task validate_data (validate_data() missing 1 required positional argument: 'df1'; 90)
[2024-05-08T14:23:15.057+0000] {local_task_job_runner.py:234} INFO - Task exited with return code 1
[2024-05-08T14:23:15.087+0000] {taskinstance.py:3312} INFO - 0 downstream tasks scheduled from follow-on schedule check
