[2024-05-07T14:27:48.781+0000] {taskinstance.py:1979} INFO - Dependencies all met for dep_context=non-requeueable deps ti=<TaskInstance: spotify_data_pipeline.validate_data manual__2024-05-07T14:25:19.462535+00:00 [queued]>
[2024-05-07T14:27:48.789+0000] {taskinstance.py:1979} INFO - Dependencies all met for dep_context=requeueable deps ti=<TaskInstance: spotify_data_pipeline.validate_data manual__2024-05-07T14:25:19.462535+00:00 [queued]>
[2024-05-07T14:27:48.789+0000] {taskinstance.py:2193} INFO - Starting attempt 2 of 2
[2024-05-07T14:27:48.801+0000] {taskinstance.py:2217} INFO - Executing <Task(PythonOperator): validate_data> on 2024-05-07 14:25:19.462535+00:00
[2024-05-07T14:27:48.808+0000] {standard_task_runner.py:60} INFO - Started process 2028 to run task
[2024-05-07T14:27:48.812+0000] {standard_task_runner.py:87} INFO - Running: ['***', 'tasks', 'run', 'spotify_data_pipeline', 'validate_data', 'manual__2024-05-07T14:25:19.462535+00:00', '--job-id', '412', '--raw', '--subdir', 'DAGS_FOLDER/main15.py', '--cfg-path', '/tmp/tmp78p7mhnu']
[2024-05-07T14:27:48.815+0000] {standard_task_runner.py:88} INFO - Job 412: Subtask validate_data
[2024-05-07T14:27:48.865+0000] {task_command.py:423} INFO - Running <TaskInstance: spotify_data_pipeline.validate_data manual__2024-05-07T14:25:19.462535+00:00 [running]> on host 8aebc95d8de6
[2024-05-07T14:27:49.016+0000] {taskinstance.py:2513} INFO - Exporting env vars: AIRFLOW_CTX_DAG_OWNER='***' AIRFLOW_CTX_DAG_ID='spotify_data_pipeline' AIRFLOW_CTX_TASK_ID='validate_data' AIRFLOW_CTX_EXECUTION_DATE='2024-05-07T14:25:19.462535+00:00' AIRFLOW_CTX_TRY_NUMBER='2' AIRFLOW_CTX_DAG_RUN_ID='manual__2024-05-07T14:25:19.462535+00:00'
[2024-05-07T14:27:49.019+0000] {taskinstance.py:2731} ERROR - Task failed with exception
Traceback (most recent call last):
  File "/home/airflow/.local/lib/python3.8/site-packages/airflow/models/taskinstance.py", line 444, in _execute_task
    result = _execute_callable(context=context, **execute_callable_kwargs)
  File "/home/airflow/.local/lib/python3.8/site-packages/airflow/models/taskinstance.py", line 414, in _execute_callable
    return execute_callable(context=context, **execute_callable_kwargs)
  File "/home/airflow/.local/lib/python3.8/site-packages/airflow/operators/python.py", line 200, in execute
    return_value = self.execute_callable()
  File "/home/airflow/.local/lib/python3.8/site-packages/airflow/operators/python.py", line 217, in execute_callable
    return self.python_callable(*self.op_args, **self.op_kwargs)
  File "/opt/airflow/dags/main15.py", line 288, in validate_data
    if df.empty:
AttributeError: 'str' object has no attribute 'empty'
[2024-05-07T14:27:49.035+0000] {taskinstance.py:1149} INFO - Marking task as FAILED. dag_id=spotify_data_pipeline, task_id=validate_data, execution_date=20240507T142519, start_date=20240507T142748, end_date=20240507T142749
[2024-05-07T14:27:49.047+0000] {standard_task_runner.py:107} ERROR - Failed to execute job 412 for task validate_data ('str' object has no attribute 'empty'; 2028)
[2024-05-07T14:27:49.066+0000] {local_task_job_runner.py:234} INFO - Task exited with return code 1
[2024-05-07T14:27:49.087+0000] {taskinstance.py:3312} INFO - 0 downstream tasks scheduled from follow-on schedule check
