[2024-05-11T16:06:54.842+0000] {taskinstance.py:1979} INFO - Dependencies all met for dep_context=non-requeueable deps ti=<TaskInstance: spotify_data_pipeline.process_and_clean_data_task manual__2024-05-11T16:06:33.286509+00:00 [queued]>
[2024-05-11T16:06:54.865+0000] {taskinstance.py:1979} INFO - Dependencies all met for dep_context=requeueable deps ti=<TaskInstance: spotify_data_pipeline.process_and_clean_data_task manual__2024-05-11T16:06:33.286509+00:00 [queued]>
[2024-05-11T16:06:54.866+0000] {taskinstance.py:2193} INFO - Starting attempt 1 of 2
[2024-05-11T16:06:54.899+0000] {taskinstance.py:2217} INFO - Executing <Task(PythonOperator): process_and_clean_data_task> on 2024-05-11 16:06:33.286509+00:00
[2024-05-11T16:06:54.907+0000] {standard_task_runner.py:60} INFO - Started process 2604 to run task
[2024-05-11T16:06:54.914+0000] {standard_task_runner.py:87} INFO - Running: ['***', 'tasks', 'run', 'spotify_data_pipeline', 'process_and_clean_data_task', 'manual__2024-05-11T16:06:33.286509+00:00', '--job-id', '820', '--raw', '--subdir', 'DAGS_FOLDER/main15.py', '--cfg-path', '/tmp/tmppv9hd5pz']
[2024-05-11T16:06:54.917+0000] {standard_task_runner.py:88} INFO - Job 820: Subtask process_and_clean_data_task
[2024-05-11T16:06:55.002+0000] {task_command.py:423} INFO - Running <TaskInstance: spotify_data_pipeline.process_and_clean_data_task manual__2024-05-11T16:06:33.286509+00:00 [running]> on host 87b4d1457810
[2024-05-11T16:06:55.121+0000] {taskinstance.py:2513} INFO - Exporting env vars: AIRFLOW_CTX_DAG_OWNER='***' AIRFLOW_CTX_DAG_ID='spotify_data_pipeline' AIRFLOW_CTX_TASK_ID='process_and_clean_data_task' AIRFLOW_CTX_EXECUTION_DATE='2024-05-11T16:06:33.286509+00:00' AIRFLOW_CTX_TRY_NUMBER='1' AIRFLOW_CTX_DAG_RUN_ID='manual__2024-05-11T16:06:33.286509+00:00'
[2024-05-11T16:06:56.742+0000] {logging_mixin.py:188} INFO - Table created successfully
[2024-05-11T16:06:56.764+0000] {taskinstance.py:2731} ERROR - Task failed with exception
Traceback (most recent call last):
  File "/home/airflow/.local/lib/python3.8/site-packages/airflow/models/taskinstance.py", line 444, in _execute_task
    result = _execute_callable(context=context, **execute_callable_kwargs)
  File "/home/airflow/.local/lib/python3.8/site-packages/airflow/models/taskinstance.py", line 414, in _execute_callable
    return execute_callable(context=context, **execute_callable_kwargs)
  File "/home/airflow/.local/lib/python3.8/site-packages/airflow/operators/python.py", line 200, in execute
    return_value = self.execute_callable()
  File "/home/airflow/.local/lib/python3.8/site-packages/airflow/operators/python.py", line 217, in execute_callable
    return self.python_callable(*self.op_args, **self.op_kwargs)
  File "/opt/airflow/dags/main15.py", line 275, in process_and_clean_data
    cur.execute(insert_query, values)
psycopg2.errors.UniqueViolation: duplicate key value violates unique constraint "songs_pkey"
DETAIL:  Key ("Track ID")=(3hBWQuSesEt8LF151dsEII) already exists.

[2024-05-11T16:06:56.781+0000] {taskinstance.py:1149} INFO - Marking task as UP_FOR_RETRY. dag_id=spotify_data_pipeline, task_id=process_and_clean_data_task, execution_date=20240511T160633, start_date=20240511T160654, end_date=20240511T160656
[2024-05-11T16:06:56.803+0000] {standard_task_runner.py:107} ERROR - Failed to execute job 820 for task process_and_clean_data_task (duplicate key value violates unique constraint "songs_pkey"
DETAIL:  Key ("Track ID")=(3hBWQuSesEt8LF151dsEII) already exists.
; 2604)
[2024-05-11T16:06:56.860+0000] {local_task_job_runner.py:234} INFO - Task exited with return code 1
[2024-05-11T16:06:56.907+0000] {taskinstance.py:3312} INFO - 0 downstream tasks scheduled from follow-on schedule check
