[2024-06-19T14:31:54.029+0000] {taskinstance.py:1979} INFO - Dependencies all met for dep_context=non-requeueable deps ti=<TaskInstance: spotify_data_pipeline.process_and_clean_data_task manual__2024-06-19T14:31:30.822397+00:00 [queued]>
[2024-06-19T14:31:54.053+0000] {taskinstance.py:1979} INFO - Dependencies all met for dep_context=requeueable deps ti=<TaskInstance: spotify_data_pipeline.process_and_clean_data_task manual__2024-06-19T14:31:30.822397+00:00 [queued]>
[2024-06-19T14:31:54.054+0000] {taskinstance.py:2193} INFO - Starting attempt 1 of 2
[2024-06-19T14:31:54.081+0000] {taskinstance.py:2217} INFO - Executing <Task(PythonOperator): process_and_clean_data_task> on 2024-06-19 14:31:30.822397+00:00
[2024-06-19T14:31:54.091+0000] {standard_task_runner.py:60} INFO - Started process 2274 to run task
[2024-06-19T14:31:54.097+0000] {standard_task_runner.py:87} INFO - Running: ['***', 'tasks', 'run', 'spotify_data_pipeline', 'process_and_clean_data_task', 'manual__2024-06-19T14:31:30.822397+00:00', '--job-id', '1228', '--raw', '--subdir', 'DAGS_FOLDER/main15.py', '--cfg-path', '/tmp/tmpndbm2e8l']
[2024-06-19T14:31:54.099+0000] {standard_task_runner.py:88} INFO - Job 1228: Subtask process_and_clean_data_task
[2024-06-19T14:31:54.179+0000] {task_command.py:423} INFO - Running <TaskInstance: spotify_data_pipeline.process_and_clean_data_task manual__2024-06-19T14:31:30.822397+00:00 [running]> on host 87b4d1457810
[2024-06-19T14:31:54.302+0000] {taskinstance.py:2513} INFO - Exporting env vars: AIRFLOW_CTX_DAG_OWNER='***' AIRFLOW_CTX_DAG_ID='spotify_data_pipeline' AIRFLOW_CTX_TASK_ID='process_and_clean_data_task' AIRFLOW_CTX_EXECUTION_DATE='2024-06-19T14:31:30.822397+00:00' AIRFLOW_CTX_TRY_NUMBER='1' AIRFLOW_CTX_DAG_RUN_ID='manual__2024-06-19T14:31:30.822397+00:00'
[2024-06-19T14:31:55.171+0000] {logging_mixin.py:188} INFO - Table created successfully
[2024-06-19T14:31:55.173+0000] {taskinstance.py:2731} ERROR - Task failed with exception
Traceback (most recent call last):
  File "/home/airflow/.local/lib/python3.8/site-packages/pandas/core/indexes/base.py", line 3653, in get_loc
    return self._engine.get_loc(casted_key)
  File "pandas/_libs/index.pyx", line 147, in pandas._libs.index.IndexEngine.get_loc
  File "pandas/_libs/index.pyx", line 176, in pandas._libs.index.IndexEngine.get_loc
  File "pandas/_libs/hashtable_class_helper.pxi", line 7080, in pandas._libs.hashtable.PyObjectHashTable.get_item
  File "pandas/_libs/hashtable_class_helper.pxi", line 7088, in pandas._libs.hashtable.PyObjectHashTable.get_item
KeyError: 'Added Date'

The above exception was the direct cause of the following exception:

Traceback (most recent call last):
  File "/home/airflow/.local/lib/python3.8/site-packages/airflow/models/taskinstance.py", line 444, in _execute_task
    result = _execute_callable(context=context, **execute_callable_kwargs)
  File "/home/airflow/.local/lib/python3.8/site-packages/airflow/models/taskinstance.py", line 414, in _execute_callable
    return execute_callable(context=context, **execute_callable_kwargs)
  File "/home/airflow/.local/lib/python3.8/site-packages/airflow/operators/python.py", line 200, in execute
    return_value = self.execute_callable()
  File "/home/airflow/.local/lib/python3.8/site-packages/airflow/operators/python.py", line 217, in execute_callable
    return self.python_callable(*self.op_args, **self.op_kwargs)
  File "/opt/airflow/dags/main15.py", line 241, in process_and_clean_data
    df['Added Date'] = pd.to_datetime(df['Added Date']).dt.date
  File "/home/airflow/.local/lib/python3.8/site-packages/pandas/core/frame.py", line 3761, in __getitem__
    indexer = self.columns.get_loc(key)
  File "/home/airflow/.local/lib/python3.8/site-packages/pandas/core/indexes/base.py", line 3655, in get_loc
    raise KeyError(key) from err
KeyError: 'Added Date'
[2024-06-19T14:31:55.193+0000] {taskinstance.py:1149} INFO - Marking task as UP_FOR_RETRY. dag_id=spotify_data_pipeline, task_id=process_and_clean_data_task, execution_date=20240619T143130, start_date=20240619T143154, end_date=20240619T143155
[2024-06-19T14:31:55.211+0000] {standard_task_runner.py:107} ERROR - Failed to execute job 1228 for task process_and_clean_data_task ('Added Date'; 2274)
[2024-06-19T14:31:55.235+0000] {local_task_job_runner.py:234} INFO - Task exited with return code 1
[2024-06-19T14:31:55.255+0000] {taskinstance.py:3312} INFO - 0 downstream tasks scheduled from follow-on schedule check
