[2024-05-07T14:07:56.230+0000] {taskinstance.py:1979} INFO - Dependencies all met for dep_context=non-requeueable deps ti=<TaskInstance: spotify_data_pipeline.validate_data manual__2024-05-07T14:06:30.577624+00:00 [queued]>
[2024-05-07T14:07:56.242+0000] {taskinstance.py:1979} INFO - Dependencies all met for dep_context=requeueable deps ti=<TaskInstance: spotify_data_pipeline.validate_data manual__2024-05-07T14:06:30.577624+00:00 [queued]>
[2024-05-07T14:07:56.243+0000] {taskinstance.py:2193} INFO - Starting attempt 2 of 2
[2024-05-07T14:07:56.261+0000] {taskinstance.py:2217} INFO - Executing <Task(PythonOperator): validate_data> on 2024-05-07 14:06:30.577624+00:00
[2024-05-07T14:07:56.269+0000] {standard_task_runner.py:60} INFO - Started process 1681 to run task
[2024-05-07T14:07:56.273+0000] {standard_task_runner.py:87} INFO - Running: ['***', 'tasks', 'run', 'spotify_data_pipeline', 'validate_data', 'manual__2024-05-07T14:06:30.577624+00:00', '--job-id', '395', '--raw', '--subdir', 'DAGS_FOLDER/how.py', '--cfg-path', '/tmp/tmpycxxu2dq']
[2024-05-07T14:07:56.290+0000] {standard_task_runner.py:88} INFO - Job 395: Subtask validate_data
[2024-05-07T14:07:56.345+0000] {task_command.py:423} INFO - Running <TaskInstance: spotify_data_pipeline.validate_data manual__2024-05-07T14:06:30.577624+00:00 [running]> on host 8aebc95d8de6
[2024-05-07T14:07:56.431+0000] {taskinstance.py:2513} INFO - Exporting env vars: AIRFLOW_CTX_DAG_OWNER='***' AIRFLOW_CTX_DAG_ID='spotify_data_pipeline' AIRFLOW_CTX_TASK_ID='validate_data' AIRFLOW_CTX_EXECUTION_DATE='2024-05-07T14:06:30.577624+00:00' AIRFLOW_CTX_TRY_NUMBER='2' AIRFLOW_CTX_DAG_RUN_ID='manual__2024-05-07T14:06:30.577624+00:00'
[2024-05-07T14:07:56.433+0000] {taskinstance.py:2731} ERROR - Task failed with exception
Traceback (most recent call last):
  File "/home/airflow/.local/lib/python3.8/site-packages/airflow/models/taskinstance.py", line 444, in _execute_task
    result = _execute_callable(context=context, **execute_callable_kwargs)
  File "/home/airflow/.local/lib/python3.8/site-packages/airflow/models/taskinstance.py", line 414, in _execute_callable
    return execute_callable(context=context, **execute_callable_kwargs)
  File "/home/airflow/.local/lib/python3.8/site-packages/airflow/operators/python.py", line 200, in execute
    return_value = self.execute_callable()
  File "/home/airflow/.local/lib/python3.8/site-packages/airflow/operators/python.py", line 217, in execute_callable
    return self.python_callable(*self.op_args, **self.op_kwargs)
TypeError: validate_data() missing 1 required positional argument: 'df1'
[2024-05-07T14:07:56.442+0000] {taskinstance.py:1149} INFO - Marking task as FAILED. dag_id=spotify_data_pipeline, task_id=validate_data, execution_date=20240507T140630, start_date=20240507T140756, end_date=20240507T140756
[2024-05-07T14:07:56.457+0000] {standard_task_runner.py:107} ERROR - Failed to execute job 395 for task validate_data (validate_data() missing 1 required positional argument: 'df1'; 1681)
[2024-05-07T14:07:56.486+0000] {local_task_job_runner.py:234} INFO - Task exited with return code 1
[2024-05-07T14:07:56.523+0000] {taskinstance.py:3312} INFO - 0 downstream tasks scheduled from follow-on schedule check
