[2024-05-08T14:50:27.347+0000] {taskinstance.py:1979} INFO - Dependencies all met for dep_context=non-requeueable deps ti=<TaskInstance: spotify_data_pipeline.validate_data manual__2024-05-08T14:49:01.277005+00:00 [queued]>
[2024-05-08T14:50:27.356+0000] {taskinstance.py:1979} INFO - Dependencies all met for dep_context=requeueable deps ti=<TaskInstance: spotify_data_pipeline.validate_data manual__2024-05-08T14:49:01.277005+00:00 [queued]>
[2024-05-08T14:50:27.357+0000] {taskinstance.py:2193} INFO - Starting attempt 2 of 2
[2024-05-08T14:50:27.371+0000] {taskinstance.py:2217} INFO - Executing <Task(PythonOperator): validate_data> on 2024-05-08 14:49:01.277005+00:00
[2024-05-08T14:50:27.376+0000] {standard_task_runner.py:60} INFO - Started process 556 to run task
[2024-05-08T14:50:27.381+0000] {standard_task_runner.py:87} INFO - Running: ['***', 'tasks', 'run', 'spotify_data_pipeline', 'validate_data', 'manual__2024-05-08T14:49:01.277005+00:00', '--job-id', '463', '--raw', '--subdir', 'DAGS_FOLDER/how.py', '--cfg-path', '/tmp/tmp4l6880ld']
[2024-05-08T14:50:27.384+0000] {standard_task_runner.py:88} INFO - Job 463: Subtask validate_data
[2024-05-08T14:50:27.431+0000] {task_command.py:423} INFO - Running <TaskInstance: spotify_data_pipeline.validate_data manual__2024-05-08T14:49:01.277005+00:00 [running]> on host 8aebc95d8de6
[2024-05-08T14:50:27.518+0000] {taskinstance.py:2513} INFO - Exporting env vars: AIRFLOW_CTX_DAG_OWNER='***' AIRFLOW_CTX_DAG_ID='spotify_data_pipeline' AIRFLOW_CTX_TASK_ID='validate_data' AIRFLOW_CTX_EXECUTION_DATE='2024-05-08T14:49:01.277005+00:00' AIRFLOW_CTX_TRY_NUMBER='2' AIRFLOW_CTX_DAG_RUN_ID='manual__2024-05-08T14:49:01.277005+00:00'
[2024-05-08T14:50:27.521+0000] {taskinstance.py:2731} ERROR - Task failed with exception
Traceback (most recent call last):
  File "/home/airflow/.local/lib/python3.8/site-packages/airflow/models/taskinstance.py", line 444, in _execute_task
    result = _execute_callable(context=context, **execute_callable_kwargs)
  File "/home/airflow/.local/lib/python3.8/site-packages/airflow/models/taskinstance.py", line 414, in _execute_callable
    return execute_callable(context=context, **execute_callable_kwargs)
  File "/home/airflow/.local/lib/python3.8/site-packages/airflow/operators/python.py", line 200, in execute
    return_value = self.execute_callable()
  File "/home/airflow/.local/lib/python3.8/site-packages/airflow/operators/python.py", line 217, in execute_callable
    return self.python_callable(*self.op_args, **self.op_kwargs)
TypeError: validate_data() missing 1 required positional argument: 'df1'
[2024-05-08T14:50:27.531+0000] {taskinstance.py:1149} INFO - Marking task as FAILED. dag_id=spotify_data_pipeline, task_id=validate_data, execution_date=20240508T144901, start_date=20240508T145027, end_date=20240508T145027
[2024-05-08T14:50:27.543+0000] {standard_task_runner.py:107} ERROR - Failed to execute job 463 for task validate_data (validate_data() missing 1 required positional argument: 'df1'; 556)
[2024-05-08T14:50:27.552+0000] {local_task_job_runner.py:234} INFO - Task exited with return code 1
[2024-05-08T14:50:27.580+0000] {taskinstance.py:3312} INFO - 0 downstream tasks scheduled from follow-on schedule check
