[2024-05-07T16:23:29.589+0000] {taskinstance.py:1979} INFO - Dependencies all met for dep_context=non-requeueable deps ti=<TaskInstance: spotify_data_pipeline.validate_data manual__2024-05-07T16:22:35.748606+00:00 [queued]>
[2024-05-07T16:23:29.599+0000] {taskinstance.py:1979} INFO - Dependencies all met for dep_context=requeueable deps ti=<TaskInstance: spotify_data_pipeline.validate_data manual__2024-05-07T16:22:35.748606+00:00 [queued]>
[2024-05-07T16:23:29.600+0000] {taskinstance.py:2193} INFO - Starting attempt 1 of 2
[2024-05-07T16:23:29.615+0000] {taskinstance.py:2217} INFO - Executing <Task(PythonOperator): validate_data> on 2024-05-07 16:22:35.748606+00:00
[2024-05-07T16:23:29.621+0000] {standard_task_runner.py:60} INFO - Started process 3667 to run task
[2024-05-07T16:23:29.625+0000] {standard_task_runner.py:87} INFO - Running: ['***', 'tasks', 'run', 'spotify_data_pipeline', 'validate_data', 'manual__2024-05-07T16:22:35.748606+00:00', '--job-id', '435', '--raw', '--subdir', 'DAGS_FOLDER/how.py', '--cfg-path', '/tmp/tmpp9bem0yw']
[2024-05-07T16:23:29.627+0000] {standard_task_runner.py:88} INFO - Job 435: Subtask validate_data
[2024-05-07T16:23:29.682+0000] {task_command.py:423} INFO - Running <TaskInstance: spotify_data_pipeline.validate_data manual__2024-05-07T16:22:35.748606+00:00 [running]> on host 8aebc95d8de6
[2024-05-07T16:23:29.811+0000] {taskinstance.py:2513} INFO - Exporting env vars: AIRFLOW_CTX_DAG_OWNER='***' AIRFLOW_CTX_DAG_ID='spotify_data_pipeline' AIRFLOW_CTX_TASK_ID='validate_data' AIRFLOW_CTX_EXECUTION_DATE='2024-05-07T16:22:35.748606+00:00' AIRFLOW_CTX_TRY_NUMBER='1' AIRFLOW_CTX_DAG_RUN_ID='manual__2024-05-07T16:22:35.748606+00:00'
[2024-05-07T16:23:29.815+0000] {taskinstance.py:2731} ERROR - Task failed with exception
Traceback (most recent call last):
  File "/home/airflow/.local/lib/python3.8/site-packages/airflow/models/taskinstance.py", line 444, in _execute_task
    result = _execute_callable(context=context, **execute_callable_kwargs)
  File "/home/airflow/.local/lib/python3.8/site-packages/airflow/models/taskinstance.py", line 414, in _execute_callable
    return execute_callable(context=context, **execute_callable_kwargs)
  File "/home/airflow/.local/lib/python3.8/site-packages/airflow/operators/python.py", line 200, in execute
    return_value = self.execute_callable()
  File "/home/airflow/.local/lib/python3.8/site-packages/airflow/operators/python.py", line 217, in execute_callable
    return self.python_callable(*self.op_args, **self.op_kwargs)
TypeError: validate_data() missing 1 required positional argument: 'df1'
[2024-05-07T16:23:29.835+0000] {taskinstance.py:1149} INFO - Marking task as UP_FOR_RETRY. dag_id=spotify_data_pipeline, task_id=validate_data, execution_date=20240507T162235, start_date=20240507T162329, end_date=20240507T162329
[2024-05-07T16:23:29.863+0000] {standard_task_runner.py:107} ERROR - Failed to execute job 435 for task validate_data (validate_data() missing 1 required positional argument: 'df1'; 3667)
[2024-05-07T16:23:29.919+0000] {local_task_job_runner.py:234} INFO - Task exited with return code 1
[2024-05-07T16:23:29.964+0000] {taskinstance.py:3312} INFO - 0 downstream tasks scheduled from follow-on schedule check
